Error while exporting Run 'ec4915d9-f6f2-4b8d-85eb-cf4b3556b2f5'
Traceback (most recent call last):
  File "/home/prjemian/Apps/miniconda3/envs/bluesky_2021_1/lib/python3.8/site-packages/event_model/__init__.py", line 1041, in _attempt_with_retries
    return func(*args, **kwargs)
  File "/home/prjemian/Apps/miniconda3/envs/bluesky_2021_1/lib/python3.8/site-packages/area_detector_handlers/handlers.py", line 181, in __init__
    super().__init__(
  File "/home/prjemian/Apps/miniconda3/envs/bluesky_2021_1/lib/python3.8/site-packages/area_detector_handlers/handlers.py", line 117, in __init__
    self.open()
  File "/home/prjemian/Apps/miniconda3/envs/bluesky_2021_1/lib/python3.8/site-packages/area_detector_handlers/handlers.py", line 137, in open
    self._file = h5py.File(self._filename, "r")
  File "/home/prjemian/Apps/miniconda3/envs/bluesky_2021_1/lib/python3.8/site-packages/h5py/_hl/files.py", line 406, in __init__
    fid = make_fid(name, mode, userblock_size,
  File "/home/prjemian/Apps/miniconda3/envs/bluesky_2021_1/lib/python3.8/site-packages/h5py/_hl/files.py", line 173, in make_fid
    fid = h5f.open(name, flags, fapl=fapl)
  File "h5py/_objects.pyx", line 54, in h5py._objects.with_phil.wrapper
  File "h5py/_objects.pyx", line 55, in h5py._objects.with_phil.wrapper
  File "h5py/h5f.pyx", line 88, in h5py.h5f.open
OSError: Unable to open file (unable to open file: name = '/tmp/docker_ioc/iocad/tmp/images/742f7926-acb6-4346-b8e8_000.h5', errno = 2, error message = 'No such file or directory', flags = 0, o_flags = 0)

The above exception was the direct cause of the following exception:

Traceback (most recent call last):
  File "/home/prjemian/Apps/miniconda3/envs/bluesky_2021_1/lib/python3.8/site-packages/databroker_pack/_pack.py", line 228, in export_catalog
    artifacts, files = export_run(
  File "/home/prjemian/Apps/miniconda3/envs/bluesky_2021_1/lib/python3.8/site-packages/databroker_pack/_pack.py", line 346, in export_run
    files[key].update(run.get_file_list(doc))
  File "/home/prjemian/Apps/miniconda3/envs/bluesky_2021_1/lib/python3.8/site-packages/databroker/core.py", line 1132, in get_file_list
    handler = self.fillers['yes'].get_handler(resource)
  File "/home/prjemian/Apps/miniconda3/envs/bluesky_2021_1/lib/python3.8/site-packages/event_model/__init__.py", line 861, in get_handler
    handler = _attempt_with_retries(
  File "/home/prjemian/Apps/miniconda3/envs/bluesky_2021_1/lib/python3.8/site-packages/event_model/__init__.py", line 1052, in _attempt_with_retries
    raise error_to_raise from error
event_model.EventModelError: Error instantiating handler class <class 'event_model.SubclassedAreaDetectorHDF5Handler'> with Resource document Resource({'spec': 'AD_HDF5', 'root': '/', 'resource_path': 'tmp/docker_ioc/iocad/tmp/images/742f7926-acb6-4346-b8e8_000.h5', 'resource_kwargs': {'frame_per_point': 1}, 'path_semantics': 'posix', 'uid': '8d53eef4-2418-41d1-bdd6-122938631ecc', 'run_start': 'ec4915d9-f6f2-4b8d-85eb-cf4b3556b2f5'}). Its 'root' field / was *not* modified by root_map.
Error while exporting Run '1219f704-d776-4f77-bc10-0acaa205dc12'
Traceback (most recent call last):
  File "/home/prjemian/Apps/miniconda3/envs/bluesky_2021_1/lib/python3.8/site-packages/event_model/__init__.py", line 1041, in _attempt_with_retries
    return func(*args, **kwargs)
  File "/home/prjemian/Apps/miniconda3/envs/bluesky_2021_1/lib/python3.8/site-packages/area_detector_handlers/handlers.py", line 181, in __init__
    super().__init__(
  File "/home/prjemian/Apps/miniconda3/envs/bluesky_2021_1/lib/python3.8/site-packages/area_detector_handlers/handlers.py", line 117, in __init__
    self.open()
  File "/home/prjemian/Apps/miniconda3/envs/bluesky_2021_1/lib/python3.8/site-packages/area_detector_handlers/handlers.py", line 137, in open
    self._file = h5py.File(self._filename, "r")
  File "/home/prjemian/Apps/miniconda3/envs/bluesky_2021_1/lib/python3.8/site-packages/h5py/_hl/files.py", line 406, in __init__
    fid = make_fid(name, mode, userblock_size,
  File "/home/prjemian/Apps/miniconda3/envs/bluesky_2021_1/lib/python3.8/site-packages/h5py/_hl/files.py", line 173, in make_fid
    fid = h5f.open(name, flags, fapl=fapl)
  File "h5py/_objects.pyx", line 54, in h5py._objects.with_phil.wrapper
  File "h5py/_objects.pyx", line 55, in h5py._objects.with_phil.wrapper
  File "h5py/h5f.pyx", line 88, in h5py.h5f.open
OSError: Unable to open file (unable to open file: name = '/tmp/docker_ioc/iocad/tmp/images/db89897f-5ec7-4eee-8dac_000.h5', errno = 2, error message = 'No such file or directory', flags = 0, o_flags = 0)

The above exception was the direct cause of the following exception:

Traceback (most recent call last):
  File "/home/prjemian/Apps/miniconda3/envs/bluesky_2021_1/lib/python3.8/site-packages/databroker_pack/_pack.py", line 228, in export_catalog
    artifacts, files = export_run(
  File "/home/prjemian/Apps/miniconda3/envs/bluesky_2021_1/lib/python3.8/site-packages/databroker_pack/_pack.py", line 346, in export_run
    files[key].update(run.get_file_list(doc))
  File "/home/prjemian/Apps/miniconda3/envs/bluesky_2021_1/lib/python3.8/site-packages/databroker/core.py", line 1132, in get_file_list
    handler = self.fillers['yes'].get_handler(resource)
  File "/home/prjemian/Apps/miniconda3/envs/bluesky_2021_1/lib/python3.8/site-packages/event_model/__init__.py", line 861, in get_handler
    handler = _attempt_with_retries(
  File "/home/prjemian/Apps/miniconda3/envs/bluesky_2021_1/lib/python3.8/site-packages/event_model/__init__.py", line 1052, in _attempt_with_retries
    raise error_to_raise from error
event_model.EventModelError: Error instantiating handler class <class 'event_model.SubclassedAreaDetectorHDF5Handler'> with Resource document Resource({'spec': 'AD_HDF5', 'root': '/', 'resource_path': 'tmp/docker_ioc/iocad/tmp/images/db89897f-5ec7-4eee-8dac_000.h5', 'resource_kwargs': {'frame_per_point': 1}, 'path_semantics': 'posix', 'uid': 'dba78d66-864f-497c-9d73-d3d2ad77dcc3', 'run_start': '1219f704-d776-4f77-bc10-0acaa205dc12'}). Its 'root' field / was *not* modified by root_map.
Error while exporting Run 'a1c743d5-b22b-42a4-a812-0d02d01f79b2'
Traceback (most recent call last):
  File "/home/prjemian/Apps/miniconda3/envs/bluesky_2021_1/lib/python3.8/site-packages/event_model/__init__.py", line 1041, in _attempt_with_retries
    return func(*args, **kwargs)
  File "/home/prjemian/Apps/miniconda3/envs/bluesky_2021_1/lib/python3.8/site-packages/area_detector_handlers/handlers.py", line 181, in __init__
    super().__init__(
  File "/home/prjemian/Apps/miniconda3/envs/bluesky_2021_1/lib/python3.8/site-packages/area_detector_handlers/handlers.py", line 117, in __init__
    self.open()
  File "/home/prjemian/Apps/miniconda3/envs/bluesky_2021_1/lib/python3.8/site-packages/area_detector_handlers/handlers.py", line 137, in open
    self._file = h5py.File(self._filename, "r")
  File "/home/prjemian/Apps/miniconda3/envs/bluesky_2021_1/lib/python3.8/site-packages/h5py/_hl/files.py", line 406, in __init__
    fid = make_fid(name, mode, userblock_size,
  File "/home/prjemian/Apps/miniconda3/envs/bluesky_2021_1/lib/python3.8/site-packages/h5py/_hl/files.py", line 173, in make_fid
    fid = h5f.open(name, flags, fapl=fapl)
  File "h5py/_objects.pyx", line 54, in h5py._objects.with_phil.wrapper
  File "h5py/_objects.pyx", line 55, in h5py._objects.with_phil.wrapper
  File "h5py/h5f.pyx", line 88, in h5py.h5f.open
OSError: Unable to open file (unable to open file: name = '/tmp/docker_ioc/iocad/tmp/images/868da491-fe39-4a7c-8801_000.h5', errno = 2, error message = 'No such file or directory', flags = 0, o_flags = 0)

The above exception was the direct cause of the following exception:

Traceback (most recent call last):
  File "/home/prjemian/Apps/miniconda3/envs/bluesky_2021_1/lib/python3.8/site-packages/databroker_pack/_pack.py", line 228, in export_catalog
    artifacts, files = export_run(
  File "/home/prjemian/Apps/miniconda3/envs/bluesky_2021_1/lib/python3.8/site-packages/databroker_pack/_pack.py", line 346, in export_run
    files[key].update(run.get_file_list(doc))
  File "/home/prjemian/Apps/miniconda3/envs/bluesky_2021_1/lib/python3.8/site-packages/databroker/core.py", line 1132, in get_file_list
    handler = self.fillers['yes'].get_handler(resource)
  File "/home/prjemian/Apps/miniconda3/envs/bluesky_2021_1/lib/python3.8/site-packages/event_model/__init__.py", line 861, in get_handler
    handler = _attempt_with_retries(
  File "/home/prjemian/Apps/miniconda3/envs/bluesky_2021_1/lib/python3.8/site-packages/event_model/__init__.py", line 1052, in _attempt_with_retries
    raise error_to_raise from error
event_model.EventModelError: Error instantiating handler class <class 'event_model.SubclassedAreaDetectorHDF5Handler'> with Resource document Resource({'spec': 'AD_HDF5', 'root': '/', 'resource_path': 'tmp/docker_ioc/iocad/tmp/images/868da491-fe39-4a7c-8801_000.h5', 'resource_kwargs': {'frame_per_point': 1}, 'path_semantics': 'posix', 'uid': '36988a7f-b8ad-4a22-9544-01bcc3166b2e', 'run_start': 'a1c743d5-b22b-42a4-a812-0d02d01f79b2'}). Its 'root' field / was *not* modified by root_map.
Error while exporting Run '33296ab3-7464-46f8-baef-4919ceef6d69'
Traceback (most recent call last):
  File "/home/prjemian/Apps/miniconda3/envs/bluesky_2021_1/lib/python3.8/site-packages/event_model/__init__.py", line 1041, in _attempt_with_retries
    return func(*args, **kwargs)
  File "/home/prjemian/Apps/miniconda3/envs/bluesky_2021_1/lib/python3.8/site-packages/area_detector_handlers/handlers.py", line 181, in __init__
    super().__init__(
  File "/home/prjemian/Apps/miniconda3/envs/bluesky_2021_1/lib/python3.8/site-packages/area_detector_handlers/handlers.py", line 117, in __init__
    self.open()
  File "/home/prjemian/Apps/miniconda3/envs/bluesky_2021_1/lib/python3.8/site-packages/area_detector_handlers/handlers.py", line 137, in open
    self._file = h5py.File(self._filename, "r")
  File "/home/prjemian/Apps/miniconda3/envs/bluesky_2021_1/lib/python3.8/site-packages/h5py/_hl/files.py", line 406, in __init__
    fid = make_fid(name, mode, userblock_size,
  File "/home/prjemian/Apps/miniconda3/envs/bluesky_2021_1/lib/python3.8/site-packages/h5py/_hl/files.py", line 173, in make_fid
    fid = h5f.open(name, flags, fapl=fapl)
  File "h5py/_objects.pyx", line 54, in h5py._objects.with_phil.wrapper
  File "h5py/_objects.pyx", line 55, in h5py._objects.with_phil.wrapper
  File "h5py/h5f.pyx", line 88, in h5py.h5f.open
OSError: Unable to open file (unable to open file: name = '/tmp/docker_ioc/iocad/tmp/images/7bb8a768-c770-41b3-b8bc_000.h5', errno = 2, error message = 'No such file or directory', flags = 0, o_flags = 0)

The above exception was the direct cause of the following exception:

Traceback (most recent call last):
  File "/home/prjemian/Apps/miniconda3/envs/bluesky_2021_1/lib/python3.8/site-packages/databroker_pack/_pack.py", line 228, in export_catalog
    artifacts, files = export_run(
  File "/home/prjemian/Apps/miniconda3/envs/bluesky_2021_1/lib/python3.8/site-packages/databroker_pack/_pack.py", line 346, in export_run
    files[key].update(run.get_file_list(doc))
  File "/home/prjemian/Apps/miniconda3/envs/bluesky_2021_1/lib/python3.8/site-packages/databroker/core.py", line 1132, in get_file_list
    handler = self.fillers['yes'].get_handler(resource)
  File "/home/prjemian/Apps/miniconda3/envs/bluesky_2021_1/lib/python3.8/site-packages/event_model/__init__.py", line 861, in get_handler
    handler = _attempt_with_retries(
  File "/home/prjemian/Apps/miniconda3/envs/bluesky_2021_1/lib/python3.8/site-packages/event_model/__init__.py", line 1052, in _attempt_with_retries
    raise error_to_raise from error
event_model.EventModelError: Error instantiating handler class <class 'event_model.SubclassedAreaDetectorHDF5Handler'> with Resource document Resource({'spec': 'AD_HDF5', 'root': '/', 'resource_path': 'tmp/docker_ioc/iocad/tmp/images/7bb8a768-c770-41b3-b8bc_000.h5', 'resource_kwargs': {'frame_per_point': 1}, 'path_semantics': 'posix', 'uid': 'b767e0a6-fe10-4900-9e70-64de1170d5ed', 'run_start': '33296ab3-7464-46f8-baef-4919ceef6d69'}). Its 'root' field / was *not* modified by root_map.
Error while exporting Run 'f7b96eb0-8dd4-49a7-a6a4-d50e25feb8dd'
Traceback (most recent call last):
  File "/home/prjemian/Apps/miniconda3/envs/bluesky_2021_1/lib/python3.8/site-packages/event_model/__init__.py", line 1041, in _attempt_with_retries
    return func(*args, **kwargs)
  File "/home/prjemian/Apps/miniconda3/envs/bluesky_2021_1/lib/python3.8/site-packages/area_detector_handlers/handlers.py", line 181, in __init__
    super().__init__(
  File "/home/prjemian/Apps/miniconda3/envs/bluesky_2021_1/lib/python3.8/site-packages/area_detector_handlers/handlers.py", line 117, in __init__
    self.open()
  File "/home/prjemian/Apps/miniconda3/envs/bluesky_2021_1/lib/python3.8/site-packages/area_detector_handlers/handlers.py", line 137, in open
    self._file = h5py.File(self._filename, "r")
  File "/home/prjemian/Apps/miniconda3/envs/bluesky_2021_1/lib/python3.8/site-packages/h5py/_hl/files.py", line 406, in __init__
    fid = make_fid(name, mode, userblock_size,
  File "/home/prjemian/Apps/miniconda3/envs/bluesky_2021_1/lib/python3.8/site-packages/h5py/_hl/files.py", line 173, in make_fid
    fid = h5f.open(name, flags, fapl=fapl)
  File "h5py/_objects.pyx", line 54, in h5py._objects.with_phil.wrapper
  File "h5py/_objects.pyx", line 55, in h5py._objects.with_phil.wrapper
  File "h5py/h5f.pyx", line 88, in h5py.h5f.open
OSError: Unable to open file (unable to open file: name = '/tmp/docker_ioc/iocad/tmp/adsimdet/2021/02/26/17f1eeaa-ad42-4cc3-beef_000.h5', errno = 2, error message = 'No such file or directory', flags = 0, o_flags = 0)

The above exception was the direct cause of the following exception:

Traceback (most recent call last):
  File "/home/prjemian/Apps/miniconda3/envs/bluesky_2021_1/lib/python3.8/site-packages/databroker_pack/_pack.py", line 228, in export_catalog
    artifacts, files = export_run(
  File "/home/prjemian/Apps/miniconda3/envs/bluesky_2021_1/lib/python3.8/site-packages/databroker_pack/_pack.py", line 346, in export_run
    files[key].update(run.get_file_list(doc))
  File "/home/prjemian/Apps/miniconda3/envs/bluesky_2021_1/lib/python3.8/site-packages/databroker/core.py", line 1132, in get_file_list
    handler = self.fillers['yes'].get_handler(resource)
  File "/home/prjemian/Apps/miniconda3/envs/bluesky_2021_1/lib/python3.8/site-packages/event_model/__init__.py", line 861, in get_handler
    handler = _attempt_with_retries(
  File "/home/prjemian/Apps/miniconda3/envs/bluesky_2021_1/lib/python3.8/site-packages/event_model/__init__.py", line 1052, in _attempt_with_retries
    raise error_to_raise from error
event_model.EventModelError: Error instantiating handler class <class 'event_model.SubclassedAreaDetectorHDF5Handler'> with Resource document Resource({'spec': 'AD_HDF5', 'root': '/', 'resource_path': 'tmp/docker_ioc/iocad/tmp/adsimdet/2021/02/26/17f1eeaa-ad42-4cc3-beef_000.h5', 'resource_kwargs': {'frame_per_point': 1}, 'path_semantics': 'posix', 'uid': '2a01dfba-4e41-403a-8de2-9cc463672544', 'run_start': 'f7b96eb0-8dd4-49a7-a6a4-d50e25feb8dd'}). Its 'root' field / was *not* modified by root_map.
Error while exporting Run '361400d1-fb29-4b4d-9fa7-86e1b1f760e3'
Traceback (most recent call last):
  File "/home/prjemian/Apps/miniconda3/envs/bluesky_2021_1/lib/python3.8/site-packages/event_model/__init__.py", line 1041, in _attempt_with_retries
    return func(*args, **kwargs)
  File "/home/prjemian/Apps/miniconda3/envs/bluesky_2021_1/lib/python3.8/site-packages/area_detector_handlers/handlers.py", line 181, in __init__
    super().__init__(
  File "/home/prjemian/Apps/miniconda3/envs/bluesky_2021_1/lib/python3.8/site-packages/area_detector_handlers/handlers.py", line 117, in __init__
    self.open()
  File "/home/prjemian/Apps/miniconda3/envs/bluesky_2021_1/lib/python3.8/site-packages/area_detector_handlers/handlers.py", line 137, in open
    self._file = h5py.File(self._filename, "r")
  File "/home/prjemian/Apps/miniconda3/envs/bluesky_2021_1/lib/python3.8/site-packages/h5py/_hl/files.py", line 406, in __init__
    fid = make_fid(name, mode, userblock_size,
  File "/home/prjemian/Apps/miniconda3/envs/bluesky_2021_1/lib/python3.8/site-packages/h5py/_hl/files.py", line 173, in make_fid
    fid = h5f.open(name, flags, fapl=fapl)
  File "h5py/_objects.pyx", line 54, in h5py._objects.with_phil.wrapper
  File "h5py/_objects.pyx", line 55, in h5py._objects.with_phil.wrapper
  File "h5py/h5f.pyx", line 88, in h5py.h5f.open
OSError: Unable to open file (unable to open file: name = '/tmp/docker_ioc/iocad/tmp/images/ed4932df-9c12-41d5-98f3_000000.h5', errno = 2, error message = 'No such file or directory', flags = 0, o_flags = 0)

The above exception was the direct cause of the following exception:

Traceback (most recent call last):
  File "/home/prjemian/Apps/miniconda3/envs/bluesky_2021_1/lib/python3.8/site-packages/databroker_pack/_pack.py", line 228, in export_catalog
    artifacts, files = export_run(
  File "/home/prjemian/Apps/miniconda3/envs/bluesky_2021_1/lib/python3.8/site-packages/databroker_pack/_pack.py", line 346, in export_run
    files[key].update(run.get_file_list(doc))
  File "/home/prjemian/Apps/miniconda3/envs/bluesky_2021_1/lib/python3.8/site-packages/databroker/core.py", line 1132, in get_file_list
    handler = self.fillers['yes'].get_handler(resource)
  File "/home/prjemian/Apps/miniconda3/envs/bluesky_2021_1/lib/python3.8/site-packages/event_model/__init__.py", line 861, in get_handler
    handler = _attempt_with_retries(
  File "/home/prjemian/Apps/miniconda3/envs/bluesky_2021_1/lib/python3.8/site-packages/event_model/__init__.py", line 1052, in _attempt_with_retries
    raise error_to_raise from error
event_model.EventModelError: Error instantiating handler class <class 'event_model.SubclassedAreaDetectorHDF5Handler'> with Resource document Resource({'spec': 'AD_HDF5', 'root': '/', 'resource_path': 'tmp/docker_ioc/iocad/tmp/images/ed4932df-9c12-41d5-98f3_000000.h5', 'resource_kwargs': {'frame_per_point': 1}, 'path_semantics': 'posix', 'uid': '4db33c1a-eb02-4288-ba30-3110e5119996', 'run_start': '361400d1-fb29-4b4d-9fa7-86e1b1f760e3'}). Its 'root' field / was *not* modified by root_map.
Error while exporting Run 'abf25cac-1c26-431f-9757-0547abc90d79'
Traceback (most recent call last):
  File "/home/prjemian/Apps/miniconda3/envs/bluesky_2021_1/lib/python3.8/site-packages/event_model/__init__.py", line 1041, in _attempt_with_retries
    return func(*args, **kwargs)
  File "/home/prjemian/Apps/miniconda3/envs/bluesky_2021_1/lib/python3.8/site-packages/area_detector_handlers/handlers.py", line 181, in __init__
    super().__init__(
  File "/home/prjemian/Apps/miniconda3/envs/bluesky_2021_1/lib/python3.8/site-packages/area_detector_handlers/handlers.py", line 117, in __init__
    self.open()
  File "/home/prjemian/Apps/miniconda3/envs/bluesky_2021_1/lib/python3.8/site-packages/area_detector_handlers/handlers.py", line 137, in open
    self._file = h5py.File(self._filename, "r")
  File "/home/prjemian/Apps/miniconda3/envs/bluesky_2021_1/lib/python3.8/site-packages/h5py/_hl/files.py", line 406, in __init__
    fid = make_fid(name, mode, userblock_size,
  File "/home/prjemian/Apps/miniconda3/envs/bluesky_2021_1/lib/python3.8/site-packages/h5py/_hl/files.py", line 173, in make_fid
    fid = h5f.open(name, flags, fapl=fapl)
  File "h5py/_objects.pyx", line 54, in h5py._objects.with_phil.wrapper
  File "h5py/_objects.pyx", line 55, in h5py._objects.with_phil.wrapper
  File "h5py/h5f.pyx", line 88, in h5py.h5f.open
OSError: Unable to open file (unable to open file: name = '/tmp/docker_ioc/iocad/tmp/images/c58a41ad-621f-4252-b1f9_000000.h5', errno = 2, error message = 'No such file or directory', flags = 0, o_flags = 0)

The above exception was the direct cause of the following exception:

Traceback (most recent call last):
  File "/home/prjemian/Apps/miniconda3/envs/bluesky_2021_1/lib/python3.8/site-packages/databroker_pack/_pack.py", line 228, in export_catalog
    artifacts, files = export_run(
  File "/home/prjemian/Apps/miniconda3/envs/bluesky_2021_1/lib/python3.8/site-packages/databroker_pack/_pack.py", line 346, in export_run
    files[key].update(run.get_file_list(doc))
  File "/home/prjemian/Apps/miniconda3/envs/bluesky_2021_1/lib/python3.8/site-packages/databroker/core.py", line 1132, in get_file_list
    handler = self.fillers['yes'].get_handler(resource)
  File "/home/prjemian/Apps/miniconda3/envs/bluesky_2021_1/lib/python3.8/site-packages/event_model/__init__.py", line 861, in get_handler
    handler = _attempt_with_retries(
  File "/home/prjemian/Apps/miniconda3/envs/bluesky_2021_1/lib/python3.8/site-packages/event_model/__init__.py", line 1052, in _attempt_with_retries
    raise error_to_raise from error
event_model.EventModelError: Error instantiating handler class <class 'event_model.SubclassedAreaDetectorHDF5Handler'> with Resource document Resource({'spec': 'AD_HDF5', 'root': '/', 'resource_path': 'tmp/docker_ioc/iocad/tmp/images/c58a41ad-621f-4252-b1f9_000000.h5', 'resource_kwargs': {'frame_per_point': 1}, 'path_semantics': 'posix', 'uid': '4c770374-3b99-4ad2-af7d-42b6623ec59f', 'run_start': 'abf25cac-1c26-431f-9757-0547abc90d79'}). Its 'root' field / was *not* modified by root_map.
Error while exporting Run '2befeb8f-8428-4697-9568-466acbd18bb0'
Traceback (most recent call last):
  File "/home/prjemian/Apps/miniconda3/envs/bluesky_2021_1/lib/python3.8/site-packages/event_model/__init__.py", line 1041, in _attempt_with_retries
    return func(*args, **kwargs)
  File "/home/prjemian/Apps/miniconda3/envs/bluesky_2021_1/lib/python3.8/site-packages/area_detector_handlers/handlers.py", line 181, in __init__
    super().__init__(
  File "/home/prjemian/Apps/miniconda3/envs/bluesky_2021_1/lib/python3.8/site-packages/area_detector_handlers/handlers.py", line 117, in __init__
    self.open()
  File "/home/prjemian/Apps/miniconda3/envs/bluesky_2021_1/lib/python3.8/site-packages/area_detector_handlers/handlers.py", line 137, in open
    self._file = h5py.File(self._filename, "r")
  File "/home/prjemian/Apps/miniconda3/envs/bluesky_2021_1/lib/python3.8/site-packages/h5py/_hl/files.py", line 406, in __init__
    fid = make_fid(name, mode, userblock_size,
  File "/home/prjemian/Apps/miniconda3/envs/bluesky_2021_1/lib/python3.8/site-packages/h5py/_hl/files.py", line 173, in make_fid
    fid = h5f.open(name, flags, fapl=fapl)
  File "h5py/_objects.pyx", line 54, in h5py._objects.with_phil.wrapper
  File "h5py/_objects.pyx", line 55, in h5py._objects.with_phil.wrapper
  File "h5py/h5f.pyx", line 88, in h5py.h5f.open
OSError: Unable to open file (unable to open file: name = '/tmp/docker_ioc/iocad/tmp/images/00b683fc-265c-4958-a447_000000.h5', errno = 2, error message = 'No such file or directory', flags = 0, o_flags = 0)

The above exception was the direct cause of the following exception:

Traceback (most recent call last):
  File "/home/prjemian/Apps/miniconda3/envs/bluesky_2021_1/lib/python3.8/site-packages/databroker_pack/_pack.py", line 228, in export_catalog
    artifacts, files = export_run(
  File "/home/prjemian/Apps/miniconda3/envs/bluesky_2021_1/lib/python3.8/site-packages/databroker_pack/_pack.py", line 346, in export_run
    files[key].update(run.get_file_list(doc))
  File "/home/prjemian/Apps/miniconda3/envs/bluesky_2021_1/lib/python3.8/site-packages/databroker/core.py", line 1132, in get_file_list
    handler = self.fillers['yes'].get_handler(resource)
  File "/home/prjemian/Apps/miniconda3/envs/bluesky_2021_1/lib/python3.8/site-packages/event_model/__init__.py", line 861, in get_handler
    handler = _attempt_with_retries(
  File "/home/prjemian/Apps/miniconda3/envs/bluesky_2021_1/lib/python3.8/site-packages/event_model/__init__.py", line 1052, in _attempt_with_retries
    raise error_to_raise from error
event_model.EventModelError: Error instantiating handler class <class 'event_model.SubclassedAreaDetectorHDF5Handler'> with Resource document Resource({'spec': 'AD_HDF5', 'root': '/', 'resource_path': 'tmp/docker_ioc/iocad/tmp/images/00b683fc-265c-4958-a447_000000.h5', 'resource_kwargs': {'frame_per_point': 1}, 'path_semantics': 'posix', 'uid': '1492bd4f-588c-4f43-9f75-d4b3cf857f4f', 'run_start': '2befeb8f-8428-4697-9568-466acbd18bb0'}). Its 'root' field / was *not* modified by root_map.
Error while exporting Run '1dbed4fc-1afe-4ff0-b71f-d57015b64723'
Traceback (most recent call last):
  File "/home/prjemian/Apps/miniconda3/envs/bluesky_2021_1/lib/python3.8/site-packages/event_model/__init__.py", line 1041, in _attempt_with_retries
    return func(*args, **kwargs)
  File "/home/prjemian/Apps/miniconda3/envs/bluesky_2021_1/lib/python3.8/site-packages/area_detector_handlers/handlers.py", line 181, in __init__
    super().__init__(
  File "/home/prjemian/Apps/miniconda3/envs/bluesky_2021_1/lib/python3.8/site-packages/area_detector_handlers/handlers.py", line 117, in __init__
    self.open()
  File "/home/prjemian/Apps/miniconda3/envs/bluesky_2021_1/lib/python3.8/site-packages/area_detector_handlers/handlers.py", line 137, in open
    self._file = h5py.File(self._filename, "r")
  File "/home/prjemian/Apps/miniconda3/envs/bluesky_2021_1/lib/python3.8/site-packages/h5py/_hl/files.py", line 406, in __init__
    fid = make_fid(name, mode, userblock_size,
  File "/home/prjemian/Apps/miniconda3/envs/bluesky_2021_1/lib/python3.8/site-packages/h5py/_hl/files.py", line 173, in make_fid
    fid = h5f.open(name, flags, fapl=fapl)
  File "h5py/_objects.pyx", line 54, in h5py._objects.with_phil.wrapper
  File "h5py/_objects.pyx", line 55, in h5py._objects.with_phil.wrapper
  File "h5py/h5f.pyx", line 88, in h5py.h5f.open
OSError: Unable to open file (unable to open file: name = '/tmp/docker_ioc/iocad/tmp/images/3c3d314e-4052-4cd1-ac17_000000.h5', errno = 2, error message = 'No such file or directory', flags = 0, o_flags = 0)

The above exception was the direct cause of the following exception:

Traceback (most recent call last):
  File "/home/prjemian/Apps/miniconda3/envs/bluesky_2021_1/lib/python3.8/site-packages/databroker_pack/_pack.py", line 228, in export_catalog
    artifacts, files = export_run(
  File "/home/prjemian/Apps/miniconda3/envs/bluesky_2021_1/lib/python3.8/site-packages/databroker_pack/_pack.py", line 346, in export_run
    files[key].update(run.get_file_list(doc))
  File "/home/prjemian/Apps/miniconda3/envs/bluesky_2021_1/lib/python3.8/site-packages/databroker/core.py", line 1132, in get_file_list
    handler = self.fillers['yes'].get_handler(resource)
  File "/home/prjemian/Apps/miniconda3/envs/bluesky_2021_1/lib/python3.8/site-packages/event_model/__init__.py", line 861, in get_handler
    handler = _attempt_with_retries(
  File "/home/prjemian/Apps/miniconda3/envs/bluesky_2021_1/lib/python3.8/site-packages/event_model/__init__.py", line 1052, in _attempt_with_retries
    raise error_to_raise from error
event_model.EventModelError: Error instantiating handler class <class 'event_model.SubclassedAreaDetectorHDF5Handler'> with Resource document Resource({'spec': 'AD_HDF5', 'root': '/', 'resource_path': 'tmp/docker_ioc/iocad/tmp/images/3c3d314e-4052-4cd1-ac17_000000.h5', 'resource_kwargs': {'frame_per_point': 1}, 'path_semantics': 'posix', 'uid': '360f1f4c-e605-4804-8721-061b679a896e', 'run_start': '1dbed4fc-1afe-4ff0-b71f-d57015b64723'}). Its 'root' field / was *not* modified by root_map.
Error while exporting Run '857eed47-e943-4031-9cb6-6002b8121bc6'
Traceback (most recent call last):
  File "/home/prjemian/Apps/miniconda3/envs/bluesky_2021_1/lib/python3.8/site-packages/event_model/__init__.py", line 1041, in _attempt_with_retries
    return func(*args, **kwargs)
  File "/home/prjemian/Apps/miniconda3/envs/bluesky_2021_1/lib/python3.8/site-packages/area_detector_handlers/handlers.py", line 181, in __init__
    super().__init__(
  File "/home/prjemian/Apps/miniconda3/envs/bluesky_2021_1/lib/python3.8/site-packages/area_detector_handlers/handlers.py", line 117, in __init__
    self.open()
  File "/home/prjemian/Apps/miniconda3/envs/bluesky_2021_1/lib/python3.8/site-packages/area_detector_handlers/handlers.py", line 137, in open
    self._file = h5py.File(self._filename, "r")
  File "/home/prjemian/Apps/miniconda3/envs/bluesky_2021_1/lib/python3.8/site-packages/h5py/_hl/files.py", line 406, in __init__
    fid = make_fid(name, mode, userblock_size,
  File "/home/prjemian/Apps/miniconda3/envs/bluesky_2021_1/lib/python3.8/site-packages/h5py/_hl/files.py", line 173, in make_fid
    fid = h5f.open(name, flags, fapl=fapl)
  File "h5py/_objects.pyx", line 54, in h5py._objects.with_phil.wrapper
  File "h5py/_objects.pyx", line 55, in h5py._objects.with_phil.wrapper
  File "h5py/h5f.pyx", line 88, in h5py.h5f.open
OSError: Unable to open file (unable to open file: name = '/tmp/docker_ioc/iocad/tmp/images/4ca59b88-da73-4e17-9a4b_000000.h5', errno = 2, error message = 'No such file or directory', flags = 0, o_flags = 0)

The above exception was the direct cause of the following exception:

Traceback (most recent call last):
  File "/home/prjemian/Apps/miniconda3/envs/bluesky_2021_1/lib/python3.8/site-packages/databroker_pack/_pack.py", line 228, in export_catalog
    artifacts, files = export_run(
  File "/home/prjemian/Apps/miniconda3/envs/bluesky_2021_1/lib/python3.8/site-packages/databroker_pack/_pack.py", line 346, in export_run
    files[key].update(run.get_file_list(doc))
  File "/home/prjemian/Apps/miniconda3/envs/bluesky_2021_1/lib/python3.8/site-packages/databroker/core.py", line 1132, in get_file_list
    handler = self.fillers['yes'].get_handler(resource)
  File "/home/prjemian/Apps/miniconda3/envs/bluesky_2021_1/lib/python3.8/site-packages/event_model/__init__.py", line 861, in get_handler
    handler = _attempt_with_retries(
  File "/home/prjemian/Apps/miniconda3/envs/bluesky_2021_1/lib/python3.8/site-packages/event_model/__init__.py", line 1052, in _attempt_with_retries
    raise error_to_raise from error
event_model.EventModelError: Error instantiating handler class <class 'event_model.SubclassedAreaDetectorHDF5Handler'> with Resource document Resource({'spec': 'AD_HDF5', 'root': '/', 'resource_path': 'tmp/docker_ioc/iocad/tmp/images/4ca59b88-da73-4e17-9a4b_000000.h5', 'resource_kwargs': {'frame_per_point': 1}, 'path_semantics': 'posix', 'uid': '1632d728-0de0-4d89-9793-91aebc2d7a98', 'run_start': '857eed47-e943-4031-9cb6-6002b8121bc6'}). Its 'root' field / was *not* modified by root_map.
Error while exporting Run 'ede0c75b-db74-4b18-9b9e-ad80240a4225'
Traceback (most recent call last):
  File "/home/prjemian/Apps/miniconda3/envs/bluesky_2021_1/lib/python3.8/site-packages/event_model/__init__.py", line 1041, in _attempt_with_retries
    return func(*args, **kwargs)
  File "/home/prjemian/Apps/miniconda3/envs/bluesky_2021_1/lib/python3.8/site-packages/area_detector_handlers/handlers.py", line 181, in __init__
    super().__init__(
  File "/home/prjemian/Apps/miniconda3/envs/bluesky_2021_1/lib/python3.8/site-packages/area_detector_handlers/handlers.py", line 117, in __init__
    self.open()
  File "/home/prjemian/Apps/miniconda3/envs/bluesky_2021_1/lib/python3.8/site-packages/area_detector_handlers/handlers.py", line 137, in open
    self._file = h5py.File(self._filename, "r")
  File "/home/prjemian/Apps/miniconda3/envs/bluesky_2021_1/lib/python3.8/site-packages/h5py/_hl/files.py", line 406, in __init__
    fid = make_fid(name, mode, userblock_size,
  File "/home/prjemian/Apps/miniconda3/envs/bluesky_2021_1/lib/python3.8/site-packages/h5py/_hl/files.py", line 173, in make_fid
    fid = h5f.open(name, flags, fapl=fapl)
  File "h5py/_objects.pyx", line 54, in h5py._objects.with_phil.wrapper
  File "h5py/_objects.pyx", line 55, in h5py._objects.with_phil.wrapper
  File "h5py/h5f.pyx", line 88, in h5py.h5f.open
OSError: Unable to open file (unable to open file: name = '/tmp/docker_ioc/iocad/tmp/images/0f0ceccc-9c3b-40aa-83f8_000000.h5', errno = 2, error message = 'No such file or directory', flags = 0, o_flags = 0)

The above exception was the direct cause of the following exception:

Traceback (most recent call last):
  File "/home/prjemian/Apps/miniconda3/envs/bluesky_2021_1/lib/python3.8/site-packages/databroker_pack/_pack.py", line 228, in export_catalog
    artifacts, files = export_run(
  File "/home/prjemian/Apps/miniconda3/envs/bluesky_2021_1/lib/python3.8/site-packages/databroker_pack/_pack.py", line 346, in export_run
    files[key].update(run.get_file_list(doc))
  File "/home/prjemian/Apps/miniconda3/envs/bluesky_2021_1/lib/python3.8/site-packages/databroker/core.py", line 1132, in get_file_list
    handler = self.fillers['yes'].get_handler(resource)
  File "/home/prjemian/Apps/miniconda3/envs/bluesky_2021_1/lib/python3.8/site-packages/event_model/__init__.py", line 861, in get_handler
    handler = _attempt_with_retries(
  File "/home/prjemian/Apps/miniconda3/envs/bluesky_2021_1/lib/python3.8/site-packages/event_model/__init__.py", line 1052, in _attempt_with_retries
    raise error_to_raise from error
event_model.EventModelError: Error instantiating handler class <class 'event_model.SubclassedAreaDetectorHDF5Handler'> with Resource document Resource({'spec': 'AD_HDF5', 'root': '/', 'resource_path': 'tmp/docker_ioc/iocad/tmp/images/0f0ceccc-9c3b-40aa-83f8_000000.h5', 'resource_kwargs': {'frame_per_point': 1}, 'path_semantics': 'posix', 'uid': 'a173d4f9-0a07-4e0c-ac48-5aaea0b3892c', 'run_start': 'ede0c75b-db74-4b18-9b9e-ad80240a4225'}). Its 'root' field / was *not* modified by root_map.
Error while exporting Run 'aa13d7d6-79e0-40ed-a432-2f411c6bb855'
Traceback (most recent call last):
  File "/home/prjemian/Apps/miniconda3/envs/bluesky_2021_1/lib/python3.8/site-packages/event_model/__init__.py", line 1041, in _attempt_with_retries
    return func(*args, **kwargs)
  File "/home/prjemian/Apps/miniconda3/envs/bluesky_2021_1/lib/python3.8/site-packages/area_detector_handlers/handlers.py", line 181, in __init__
    super().__init__(
  File "/home/prjemian/Apps/miniconda3/envs/bluesky_2021_1/lib/python3.8/site-packages/area_detector_handlers/handlers.py", line 117, in __init__
    self.open()
  File "/home/prjemian/Apps/miniconda3/envs/bluesky_2021_1/lib/python3.8/site-packages/area_detector_handlers/handlers.py", line 137, in open
    self._file = h5py.File(self._filename, "r")
  File "/home/prjemian/Apps/miniconda3/envs/bluesky_2021_1/lib/python3.8/site-packages/h5py/_hl/files.py", line 406, in __init__
    fid = make_fid(name, mode, userblock_size,
  File "/home/prjemian/Apps/miniconda3/envs/bluesky_2021_1/lib/python3.8/site-packages/h5py/_hl/files.py", line 173, in make_fid
    fid = h5f.open(name, flags, fapl=fapl)
  File "h5py/_objects.pyx", line 54, in h5py._objects.with_phil.wrapper
  File "h5py/_objects.pyx", line 55, in h5py._objects.with_phil.wrapper
  File "h5py/h5f.pyx", line 88, in h5py.h5f.open
OSError: Unable to open file (unable to open file: name = '/tmp/docker_ioc/iocad/tmp/images/169f1d9f-9ee9-4775-9b86_000000.h5', errno = 2, error message = 'No such file or directory', flags = 0, o_flags = 0)

The above exception was the direct cause of the following exception:

Traceback (most recent call last):
  File "/home/prjemian/Apps/miniconda3/envs/bluesky_2021_1/lib/python3.8/site-packages/databroker_pack/_pack.py", line 228, in export_catalog
    artifacts, files = export_run(
  File "/home/prjemian/Apps/miniconda3/envs/bluesky_2021_1/lib/python3.8/site-packages/databroker_pack/_pack.py", line 346, in export_run
    files[key].update(run.get_file_list(doc))
  File "/home/prjemian/Apps/miniconda3/envs/bluesky_2021_1/lib/python3.8/site-packages/databroker/core.py", line 1132, in get_file_list
    handler = self.fillers['yes'].get_handler(resource)
  File "/home/prjemian/Apps/miniconda3/envs/bluesky_2021_1/lib/python3.8/site-packages/event_model/__init__.py", line 861, in get_handler
    handler = _attempt_with_retries(
  File "/home/prjemian/Apps/miniconda3/envs/bluesky_2021_1/lib/python3.8/site-packages/event_model/__init__.py", line 1052, in _attempt_with_retries
    raise error_to_raise from error
event_model.EventModelError: Error instantiating handler class <class 'event_model.SubclassedAreaDetectorHDF5Handler'> with Resource document Resource({'spec': 'AD_HDF5', 'root': '/', 'resource_path': 'tmp/docker_ioc/iocad/tmp/images/169f1d9f-9ee9-4775-9b86_000000.h5', 'resource_kwargs': {'frame_per_point': 1}, 'path_semantics': 'posix', 'uid': '055b1882-1180-4ef7-9a03-291c5cc74ba1', 'run_start': 'aa13d7d6-79e0-40ed-a432-2f411c6bb855'}). Its 'root' field / was *not* modified by root_map.
Error while exporting Run '950a22e4-734f-438b-a9d4-6727d905988c'
Traceback (most recent call last):
  File "/home/prjemian/Apps/miniconda3/envs/bluesky_2021_1/lib/python3.8/site-packages/event_model/__init__.py", line 1041, in _attempt_with_retries
    return func(*args, **kwargs)
  File "/home/prjemian/Apps/miniconda3/envs/bluesky_2021_1/lib/python3.8/site-packages/area_detector_handlers/handlers.py", line 181, in __init__
    super().__init__(
  File "/home/prjemian/Apps/miniconda3/envs/bluesky_2021_1/lib/python3.8/site-packages/area_detector_handlers/handlers.py", line 117, in __init__
    self.open()
  File "/home/prjemian/Apps/miniconda3/envs/bluesky_2021_1/lib/python3.8/site-packages/area_detector_handlers/handlers.py", line 137, in open
    self._file = h5py.File(self._filename, "r")
  File "/home/prjemian/Apps/miniconda3/envs/bluesky_2021_1/lib/python3.8/site-packages/h5py/_hl/files.py", line 406, in __init__
    fid = make_fid(name, mode, userblock_size,
  File "/home/prjemian/Apps/miniconda3/envs/bluesky_2021_1/lib/python3.8/site-packages/h5py/_hl/files.py", line 173, in make_fid
    fid = h5f.open(name, flags, fapl=fapl)
  File "h5py/_objects.pyx", line 54, in h5py._objects.with_phil.wrapper
  File "h5py/_objects.pyx", line 55, in h5py._objects.with_phil.wrapper
  File "h5py/h5f.pyx", line 88, in h5py.h5f.open
OSError: Unable to open file (unable to open file: name = '/tmp/docker_ioc/iocad/tmp/images/0a2f6f6d-b8c1-425b-badb_000000.h5', errno = 2, error message = 'No such file or directory', flags = 0, o_flags = 0)

The above exception was the direct cause of the following exception:

Traceback (most recent call last):
  File "/home/prjemian/Apps/miniconda3/envs/bluesky_2021_1/lib/python3.8/site-packages/databroker_pack/_pack.py", line 228, in export_catalog
    artifacts, files = export_run(
  File "/home/prjemian/Apps/miniconda3/envs/bluesky_2021_1/lib/python3.8/site-packages/databroker_pack/_pack.py", line 346, in export_run
    files[key].update(run.get_file_list(doc))
  File "/home/prjemian/Apps/miniconda3/envs/bluesky_2021_1/lib/python3.8/site-packages/databroker/core.py", line 1132, in get_file_list
    handler = self.fillers['yes'].get_handler(resource)
  File "/home/prjemian/Apps/miniconda3/envs/bluesky_2021_1/lib/python3.8/site-packages/event_model/__init__.py", line 861, in get_handler
    handler = _attempt_with_retries(
  File "/home/prjemian/Apps/miniconda3/envs/bluesky_2021_1/lib/python3.8/site-packages/event_model/__init__.py", line 1052, in _attempt_with_retries
    raise error_to_raise from error
event_model.EventModelError: Error instantiating handler class <class 'event_model.SubclassedAreaDetectorHDF5Handler'> with Resource document Resource({'spec': 'AD_HDF5', 'root': '/', 'resource_path': 'tmp/docker_ioc/iocad/tmp/images/0a2f6f6d-b8c1-425b-badb_000000.h5', 'resource_kwargs': {'frame_per_point': 1}, 'path_semantics': 'posix', 'uid': '249c1ea9-2db9-4c71-b6e4-08b4b2887ac1', 'run_start': '950a22e4-734f-438b-a9d4-6727d905988c'}). Its 'root' field / was *not* modified by root_map.
Error while exporting Run 'c49f2048-f318-4d8b-8a41-feda20e7981c'
Traceback (most recent call last):
  File "/home/prjemian/Apps/miniconda3/envs/bluesky_2021_1/lib/python3.8/site-packages/event_model/__init__.py", line 1041, in _attempt_with_retries
    return func(*args, **kwargs)
  File "/home/prjemian/Apps/miniconda3/envs/bluesky_2021_1/lib/python3.8/site-packages/area_detector_handlers/handlers.py", line 181, in __init__
    super().__init__(
  File "/home/prjemian/Apps/miniconda3/envs/bluesky_2021_1/lib/python3.8/site-packages/area_detector_handlers/handlers.py", line 117, in __init__
    self.open()
  File "/home/prjemian/Apps/miniconda3/envs/bluesky_2021_1/lib/python3.8/site-packages/area_detector_handlers/handlers.py", line 137, in open
    self._file = h5py.File(self._filename, "r")
  File "/home/prjemian/Apps/miniconda3/envs/bluesky_2021_1/lib/python3.8/site-packages/h5py/_hl/files.py", line 406, in __init__
    fid = make_fid(name, mode, userblock_size,
  File "/home/prjemian/Apps/miniconda3/envs/bluesky_2021_1/lib/python3.8/site-packages/h5py/_hl/files.py", line 173, in make_fid
    fid = h5f.open(name, flags, fapl=fapl)
  File "h5py/_objects.pyx", line 54, in h5py._objects.with_phil.wrapper
  File "h5py/_objects.pyx", line 55, in h5py._objects.with_phil.wrapper
  File "h5py/h5f.pyx", line 88, in h5py.h5f.open
OSError: Unable to open file (unable to open file: name = '/tmp/docker_ioc/iocad/tmp/images/fdef70ad-54cd-4dea-bad1_000000.h5', errno = 2, error message = 'No such file or directory', flags = 0, o_flags = 0)

The above exception was the direct cause of the following exception:

Traceback (most recent call last):
  File "/home/prjemian/Apps/miniconda3/envs/bluesky_2021_1/lib/python3.8/site-packages/databroker_pack/_pack.py", line 228, in export_catalog
    artifacts, files = export_run(
  File "/home/prjemian/Apps/miniconda3/envs/bluesky_2021_1/lib/python3.8/site-packages/databroker_pack/_pack.py", line 346, in export_run
    files[key].update(run.get_file_list(doc))
  File "/home/prjemian/Apps/miniconda3/envs/bluesky_2021_1/lib/python3.8/site-packages/databroker/core.py", line 1132, in get_file_list
    handler = self.fillers['yes'].get_handler(resource)
  File "/home/prjemian/Apps/miniconda3/envs/bluesky_2021_1/lib/python3.8/site-packages/event_model/__init__.py", line 861, in get_handler
    handler = _attempt_with_retries(
  File "/home/prjemian/Apps/miniconda3/envs/bluesky_2021_1/lib/python3.8/site-packages/event_model/__init__.py", line 1052, in _attempt_with_retries
    raise error_to_raise from error
event_model.EventModelError: Error instantiating handler class <class 'event_model.SubclassedAreaDetectorHDF5Handler'> with Resource document Resource({'spec': 'AD_HDF5', 'root': '/', 'resource_path': 'tmp/docker_ioc/iocad/tmp/images/fdef70ad-54cd-4dea-bad1_000000.h5', 'resource_kwargs': {'frame_per_point': 1}, 'path_semantics': 'posix', 'uid': 'c3485979-c326-45f6-83f7-e22b0429bef3', 'run_start': 'c49f2048-f318-4d8b-8a41-feda20e7981c'}). Its 'root' field / was *not* modified by root_map.
Error while exporting Run 'fd39b228-6086-472c-afd4-affc7c2ac819'
Traceback (most recent call last):
  File "/home/prjemian/Apps/miniconda3/envs/bluesky_2021_1/lib/python3.8/site-packages/event_model/__init__.py", line 1041, in _attempt_with_retries
    return func(*args, **kwargs)
  File "/home/prjemian/Apps/miniconda3/envs/bluesky_2021_1/lib/python3.8/site-packages/area_detector_handlers/handlers.py", line 181, in __init__
    super().__init__(
  File "/home/prjemian/Apps/miniconda3/envs/bluesky_2021_1/lib/python3.8/site-packages/area_detector_handlers/handlers.py", line 117, in __init__
    self.open()
  File "/home/prjemian/Apps/miniconda3/envs/bluesky_2021_1/lib/python3.8/site-packages/area_detector_handlers/handlers.py", line 137, in open
    self._file = h5py.File(self._filename, "r")
  File "/home/prjemian/Apps/miniconda3/envs/bluesky_2021_1/lib/python3.8/site-packages/h5py/_hl/files.py", line 406, in __init__
    fid = make_fid(name, mode, userblock_size,
  File "/home/prjemian/Apps/miniconda3/envs/bluesky_2021_1/lib/python3.8/site-packages/h5py/_hl/files.py", line 173, in make_fid
    fid = h5f.open(name, flags, fapl=fapl)
  File "h5py/_objects.pyx", line 54, in h5py._objects.with_phil.wrapper
  File "h5py/_objects.pyx", line 55, in h5py._objects.with_phil.wrapper
  File "h5py/h5f.pyx", line 88, in h5py.h5f.open
OSError: Unable to open file (unable to open file: name = '/tmp/docker_ioc/iocad/tmp/images/6197fce0-b597-4c34-92b5_000000.h5', errno = 2, error message = 'No such file or directory', flags = 0, o_flags = 0)

The above exception was the direct cause of the following exception:

Traceback (most recent call last):
  File "/home/prjemian/Apps/miniconda3/envs/bluesky_2021_1/lib/python3.8/site-packages/databroker_pack/_pack.py", line 228, in export_catalog
    artifacts, files = export_run(
  File "/home/prjemian/Apps/miniconda3/envs/bluesky_2021_1/lib/python3.8/site-packages/databroker_pack/_pack.py", line 346, in export_run
    files[key].update(run.get_file_list(doc))
  File "/home/prjemian/Apps/miniconda3/envs/bluesky_2021_1/lib/python3.8/site-packages/databroker/core.py", line 1132, in get_file_list
    handler = self.fillers['yes'].get_handler(resource)
  File "/home/prjemian/Apps/miniconda3/envs/bluesky_2021_1/lib/python3.8/site-packages/event_model/__init__.py", line 861, in get_handler
    handler = _attempt_with_retries(
  File "/home/prjemian/Apps/miniconda3/envs/bluesky_2021_1/lib/python3.8/site-packages/event_model/__init__.py", line 1052, in _attempt_with_retries
    raise error_to_raise from error
event_model.EventModelError: Error instantiating handler class <class 'event_model.SubclassedAreaDetectorHDF5Handler'> with Resource document Resource({'spec': 'AD_HDF5', 'root': '/', 'resource_path': 'tmp/docker_ioc/iocad/tmp/images/6197fce0-b597-4c34-92b5_000000.h5', 'resource_kwargs': {'frame_per_point': 1}, 'path_semantics': 'posix', 'uid': '0bce8dc2-a124-4f4a-8541-bb4129ebe9cb', 'run_start': 'fd39b228-6086-472c-afd4-affc7c2ac819'}). Its 'root' field / was *not* modified by root_map.
Error while exporting Run 'c5f59314-8827-42dc-887b-9430dde84eea'
Traceback (most recent call last):
  File "/home/prjemian/Apps/miniconda3/envs/bluesky_2021_1/lib/python3.8/site-packages/event_model/__init__.py", line 1041, in _attempt_with_retries
    return func(*args, **kwargs)
  File "/home/prjemian/Apps/miniconda3/envs/bluesky_2021_1/lib/python3.8/site-packages/area_detector_handlers/handlers.py", line 181, in __init__
    super().__init__(
  File "/home/prjemian/Apps/miniconda3/envs/bluesky_2021_1/lib/python3.8/site-packages/area_detector_handlers/handlers.py", line 117, in __init__
    self.open()
  File "/home/prjemian/Apps/miniconda3/envs/bluesky_2021_1/lib/python3.8/site-packages/area_detector_handlers/handlers.py", line 137, in open
    self._file = h5py.File(self._filename, "r")
  File "/home/prjemian/Apps/miniconda3/envs/bluesky_2021_1/lib/python3.8/site-packages/h5py/_hl/files.py", line 406, in __init__
    fid = make_fid(name, mode, userblock_size,
  File "/home/prjemian/Apps/miniconda3/envs/bluesky_2021_1/lib/python3.8/site-packages/h5py/_hl/files.py", line 173, in make_fid
    fid = h5f.open(name, flags, fapl=fapl)
  File "h5py/_objects.pyx", line 54, in h5py._objects.with_phil.wrapper
  File "h5py/_objects.pyx", line 55, in h5py._objects.with_phil.wrapper
  File "h5py/h5f.pyx", line 88, in h5py.h5f.open
OSError: Unable to open file (unable to open file: name = '/tmp/docker_ioc/iocad/tmp/adsimdet/2021/02/25/ecf7acf2-cf93-4f5c-801b_-001.h5', errno = 2, error message = 'No such file or directory', flags = 0, o_flags = 0)

The above exception was the direct cause of the following exception:

Traceback (most recent call last):
  File "/home/prjemian/Apps/miniconda3/envs/bluesky_2021_1/lib/python3.8/site-packages/databroker_pack/_pack.py", line 228, in export_catalog
    artifacts, files = export_run(
  File "/home/prjemian/Apps/miniconda3/envs/bluesky_2021_1/lib/python3.8/site-packages/databroker_pack/_pack.py", line 346, in export_run
    files[key].update(run.get_file_list(doc))
  File "/home/prjemian/Apps/miniconda3/envs/bluesky_2021_1/lib/python3.8/site-packages/databroker/core.py", line 1132, in get_file_list
    handler = self.fillers['yes'].get_handler(resource)
  File "/home/prjemian/Apps/miniconda3/envs/bluesky_2021_1/lib/python3.8/site-packages/event_model/__init__.py", line 861, in get_handler
    handler = _attempt_with_retries(
  File "/home/prjemian/Apps/miniconda3/envs/bluesky_2021_1/lib/python3.8/site-packages/event_model/__init__.py", line 1052, in _attempt_with_retries
    raise error_to_raise from error
event_model.EventModelError: Error instantiating handler class <class 'event_model.SubclassedAreaDetectorHDF5Handler'> with Resource document Resource({'spec': 'AD_HDF5', 'root': '/', 'resource_path': 'tmp/docker_ioc/iocad/tmp/adsimdet/2021/02/25/ecf7acf2-cf93-4f5c-801b_-001.h5', 'resource_kwargs': {'frame_per_point': 1}, 'path_semantics': 'posix', 'uid': 'be0747a6-e419-4c8d-a841-f87a1eef3ded', 'run_start': 'c5f59314-8827-42dc-887b-9430dde84eea'}). Its 'root' field / was *not* modified by root_map.
Error while exporting Run '56bdfb2c-b2cb-4b75-a026-1f2f7b085b7d'
Traceback (most recent call last):
  File "/home/prjemian/Apps/miniconda3/envs/bluesky_2021_1/lib/python3.8/site-packages/event_model/__init__.py", line 1041, in _attempt_with_retries
    return func(*args, **kwargs)
  File "/home/prjemian/Apps/miniconda3/envs/bluesky_2021_1/lib/python3.8/site-packages/area_detector_handlers/handlers.py", line 181, in __init__
    super().__init__(
  File "/home/prjemian/Apps/miniconda3/envs/bluesky_2021_1/lib/python3.8/site-packages/area_detector_handlers/handlers.py", line 117, in __init__
    self.open()
  File "/home/prjemian/Apps/miniconda3/envs/bluesky_2021_1/lib/python3.8/site-packages/area_detector_handlers/handlers.py", line 137, in open
    self._file = h5py.File(self._filename, "r")
  File "/home/prjemian/Apps/miniconda3/envs/bluesky_2021_1/lib/python3.8/site-packages/h5py/_hl/files.py", line 406, in __init__
    fid = make_fid(name, mode, userblock_size,
  File "/home/prjemian/Apps/miniconda3/envs/bluesky_2021_1/lib/python3.8/site-packages/h5py/_hl/files.py", line 173, in make_fid
    fid = h5f.open(name, flags, fapl=fapl)
  File "h5py/_objects.pyx", line 54, in h5py._objects.with_phil.wrapper
  File "h5py/_objects.pyx", line 55, in h5py._objects.with_phil.wrapper
  File "h5py/h5f.pyx", line 88, in h5py.h5f.open
OSError: Unable to open file (unable to open file: name = '/tmp/docker_ioc/iocad/tmp/adsimdet/2021/02/25/62051eda-27b0-4462-bd69_-001.h5', errno = 2, error message = 'No such file or directory', flags = 0, o_flags = 0)

The above exception was the direct cause of the following exception:

Traceback (most recent call last):
  File "/home/prjemian/Apps/miniconda3/envs/bluesky_2021_1/lib/python3.8/site-packages/databroker_pack/_pack.py", line 228, in export_catalog
    artifacts, files = export_run(
  File "/home/prjemian/Apps/miniconda3/envs/bluesky_2021_1/lib/python3.8/site-packages/databroker_pack/_pack.py", line 346, in export_run
    files[key].update(run.get_file_list(doc))
  File "/home/prjemian/Apps/miniconda3/envs/bluesky_2021_1/lib/python3.8/site-packages/databroker/core.py", line 1132, in get_file_list
    handler = self.fillers['yes'].get_handler(resource)
  File "/home/prjemian/Apps/miniconda3/envs/bluesky_2021_1/lib/python3.8/site-packages/event_model/__init__.py", line 861, in get_handler
    handler = _attempt_with_retries(
  File "/home/prjemian/Apps/miniconda3/envs/bluesky_2021_1/lib/python3.8/site-packages/event_model/__init__.py", line 1052, in _attempt_with_retries
    raise error_to_raise from error
event_model.EventModelError: Error instantiating handler class <class 'event_model.SubclassedAreaDetectorHDF5Handler'> with Resource document Resource({'spec': 'AD_HDF5', 'root': '/', 'resource_path': 'tmp/docker_ioc/iocad/tmp/adsimdet/2021/02/25/62051eda-27b0-4462-bd69_-001.h5', 'resource_kwargs': {'frame_per_point': 1}, 'path_semantics': 'posix', 'uid': '1e1e1126-c070-4a9a-8630-f16d4a99fb08', 'run_start': '56bdfb2c-b2cb-4b75-a026-1f2f7b085b7d'}). Its 'root' field / was *not* modified by root_map.
Error while exporting Run '8253dc63-20a2-4099-a739-71fd3eaca7d0'
Traceback (most recent call last):
  File "/home/prjemian/Apps/miniconda3/envs/bluesky_2021_1/lib/python3.8/site-packages/event_model/__init__.py", line 1041, in _attempt_with_retries
    return func(*args, **kwargs)
  File "/home/prjemian/Apps/miniconda3/envs/bluesky_2021_1/lib/python3.8/site-packages/area_detector_handlers/handlers.py", line 181, in __init__
    super().__init__(
  File "/home/prjemian/Apps/miniconda3/envs/bluesky_2021_1/lib/python3.8/site-packages/area_detector_handlers/handlers.py", line 117, in __init__
    self.open()
  File "/home/prjemian/Apps/miniconda3/envs/bluesky_2021_1/lib/python3.8/site-packages/area_detector_handlers/handlers.py", line 137, in open
    self._file = h5py.File(self._filename, "r")
  File "/home/prjemian/Apps/miniconda3/envs/bluesky_2021_1/lib/python3.8/site-packages/h5py/_hl/files.py", line 406, in __init__
    fid = make_fid(name, mode, userblock_size,
  File "/home/prjemian/Apps/miniconda3/envs/bluesky_2021_1/lib/python3.8/site-packages/h5py/_hl/files.py", line 173, in make_fid
    fid = h5f.open(name, flags, fapl=fapl)
  File "h5py/_objects.pyx", line 54, in h5py._objects.with_phil.wrapper
  File "h5py/_objects.pyx", line 55, in h5py._objects.with_phil.wrapper
  File "h5py/h5f.pyx", line 88, in h5py.h5f.open
OSError: Unable to open file (unable to open file: name = '/tmp/docker_ioc/iocad/tmp/adsimdet/2021/02/25/d5d2d254-11a6-4e98-89b9_-001.h5', errno = 2, error message = 'No such file or directory', flags = 0, o_flags = 0)

The above exception was the direct cause of the following exception:

Traceback (most recent call last):
  File "/home/prjemian/Apps/miniconda3/envs/bluesky_2021_1/lib/python3.8/site-packages/databroker_pack/_pack.py", line 228, in export_catalog
    artifacts, files = export_run(
  File "/home/prjemian/Apps/miniconda3/envs/bluesky_2021_1/lib/python3.8/site-packages/databroker_pack/_pack.py", line 346, in export_run
    files[key].update(run.get_file_list(doc))
  File "/home/prjemian/Apps/miniconda3/envs/bluesky_2021_1/lib/python3.8/site-packages/databroker/core.py", line 1132, in get_file_list
    handler = self.fillers['yes'].get_handler(resource)
  File "/home/prjemian/Apps/miniconda3/envs/bluesky_2021_1/lib/python3.8/site-packages/event_model/__init__.py", line 861, in get_handler
    handler = _attempt_with_retries(
  File "/home/prjemian/Apps/miniconda3/envs/bluesky_2021_1/lib/python3.8/site-packages/event_model/__init__.py", line 1052, in _attempt_with_retries
    raise error_to_raise from error
event_model.EventModelError: Error instantiating handler class <class 'event_model.SubclassedAreaDetectorHDF5Handler'> with Resource document Resource({'spec': 'AD_HDF5', 'root': '/', 'resource_path': 'tmp/docker_ioc/iocad/tmp/adsimdet/2021/02/25/d5d2d254-11a6-4e98-89b9_-001.h5', 'resource_kwargs': {'frame_per_point': 1}, 'path_semantics': 'posix', 'uid': '028bb8cc-5ad3-4180-afd8-ecb716c382da', 'run_start': '8253dc63-20a2-4099-a739-71fd3eaca7d0'}). Its 'root' field / was *not* modified by root_map.
